Watching for file changes with StatReloader
[17/Nov/2024 21:33:42] "GET /QueryManager/ HTTP/1.1" 200 13065
[17/Nov/2024 21:33:42] "GET /QueryManager/media/profile_pics/ironman.jfif HTTP/1.1" 304 0
C:\inetpub\wwwroot\QueryManager\core\settings.py changed, reloading.
Performing system checks...

System check identified no issues (0 silenced).
November 17, 2024 - 21:33:42
Django version 4.2.16, using settings 'core.settings'
Starting development server at http://127.0.0.1:22915/
Quit the server with CTRL-BREAK.

Performing system checks...

System check identified no issues (0 silenced).
November 17, 2024 - 21:34:25
Django version 4.2.16, using settings 'core.settings'
Starting development server at http://127.0.0.1:22915/
Quit the server with CTRL-BREAK.

[17/Nov/2024 21:36:21] "GET /QueryManager/ HTTP/1.1" 200 13035
[17/Nov/2024 21:36:21] "GET /QueryManager/static/bootstrap.min.css HTTP/1.1" 404 179
[17/Nov/2024 21:36:21] "GET /QueryManager/static/custom.css HTTP/1.1" 404 179
[17/Nov/2024 21:36:21] "GET /QueryManager/static/query_manager.png HTTP/1.1" 404 179
[17/Nov/2024 21:36:21] "GET /QueryManager/static/profile_pics/default2.jpg HTTP/1.1" 404 179
Performing system checks...

System check identified no issues (0 silenced).
November 17, 2024 - 21:36:14
Django version 4.2.16, using settings 'core.settings'
Starting development server at http://127.0.0.1:22915/
Quit the server with CTRL-BREAK.

Exception in thread django-main-thread:
Traceback (most recent call last):
  File "C:\Python313\Lib\threading.py", line 1041, in _bootstrap_inner
    self.run()
    ~~~~~~~~^^
  File "C:\Python313\Lib\threading.py", line 992, in run
    self._target(*self._args, **self._kwargs)
    ~~~~~~~~~~~~^^^^^^^^^^^^^^^^^^^^^^^^^^^^^
  File "C:\Python313\Lib\site-packages\django\utils\autoreload.py", line 64, in wrapper
    fn(*args, **kwargs)
    ~~^^^^^^^^^^^^^^^^^
  File "C:\Python313\Lib\site-packages\django\core\management\commands\runserver.py", line 133, in inner_run
    self.check(display_num_errors=True)
    ~~~~~~~~~~^^^^^^^^^^^^^^^^^^^^^^^^^
  File "C:\Python313\Lib\site-packages\django\core\management\base.py", line 485, in check
    all_issues = checks.run_checks(
        app_configs=app_configs,
    ...<2 lines>...
        databases=databases,
    )
  File "C:\Python313\Lib\site-packages\django\core\checks\registry.py", line 88, in run_checks
    new_errors = check(app_configs=app_configs, databases=databases)
  File "C:\Python313\Lib\site-packages\django\core\checks\urls.py", line 14, in check_url_config
    return check_resolver(resolver)
  File "C:\Python313\Lib\site-packages\django\core\checks\urls.py", line 24, in check_resolver
    return check_method()
  File "C:\Python313\Lib\site-packages\django\urls\resolvers.py", line 494, in check
    for pattern in self.url_patterns:
                   ^^^^^^^^^^^^^^^^^
  File "C:\Python313\Lib\site-packages\django\utils\functional.py", line 57, in __get__
    res = instance.__dict__[self.name] = self.func(instance)
                                         ~~~~~~~~~^^^^^^^^^^
  File "C:\Python313\Lib\site-packages\django\urls\resolvers.py", line 715, in url_patterns
    patterns = getattr(self.urlconf_module, "urlpatterns", self.urlconf_module)
                       ^^^^^^^^^^^^^^^^^^^
  File "C:\Python313\Lib\site-packages\django\utils\functional.py", line 57, in __get__
    res = instance.__dict__[self.name] = self.func(instance)
                                         ~~~~~~~~~^^^^^^^^^^
  File "C:\Python313\Lib\site-packages\django\urls\resolvers.py", line 708, in urlconf_module
    return import_module(self.urlconf_name)
  File "C:\Python313\Lib\importlib\__init__.py", line 88, in import_module
    return _bootstrap._gcd_import(name[level:], package, level)
           ~~~~~~~~~~~~~~~~~~~~~~^^^^^^^^^^^^^^^^^^^^^^^^^^^^^^
  File "<frozen importlib._bootstrap>", line 1387, in _gcd_import
  File "<frozen importlib._bootstrap>", line 1360, in _find_and_load
  File "<frozen importlib._bootstrap>", line 1331, in _find_and_load_unlocked
  File "<frozen importlib._bootstrap>", line 935, in _load_unlocked
  File "<frozen importlib._bootstrap_external>", line 1022, in exec_module
  File "<frozen importlib._bootstrap>", line 488, in _call_with_frames_removed
  File "C:\inetpub\wwwroot\QueryManager\core\urls.py", line 23, in <module>
    re_path(r'^QueryManager/media/(?P<path>.*)$', serve,{'document_root': settings.MEDIA_ROOT}),
    ^^^^^^^
NameError: name 're_path' is not defined
Performing system checks...

Exception in thread django-main-thread:
Traceback (most recent call last):
  File "C:\Python313\Lib\threading.py", line 1041, in _bootstrap_inner
    self.run()
    ~~~~~~~~^^
  File "C:\Python313\Lib\threading.py", line 992, in run
    self._target(*self._args, **self._kwargs)
    ~~~~~~~~~~~~^^^^^^^^^^^^^^^^^^^^^^^^^^^^^
  File "C:\Python313\Lib\site-packages\django\utils\autoreload.py", line 64, in wrapper
    fn(*args, **kwargs)
    ~~^^^^^^^^^^^^^^^^^
  File "C:\Python313\Lib\site-packages\django\core\management\commands\runserver.py", line 133, in inner_run
    self.check(display_num_errors=True)
    ~~~~~~~~~~^^^^^^^^^^^^^^^^^^^^^^^^^
  File "C:\Python313\Lib\site-packages\django\core\management\base.py", line 485, in check
    all_issues = checks.run_checks(
        app_configs=app_configs,
    ...<2 lines>...
        databases=databases,
    )
  File "C:\Python313\Lib\site-packages\django\core\checks\registry.py", line 88, in run_checks
    new_errors = check(app_configs=app_configs, databases=databases)
  File "C:\Python313\Lib\site-packages\django\core\checks\urls.py", line 14, in check_url_config
    return check_resolver(resolver)
  File "C:\Python313\Lib\site-packages\django\core\checks\urls.py", line 24, in check_resolver
    return check_method()
  File "C:\Python313\Lib\site-packages\django\urls\resolvers.py", line 494, in check
    for pattern in self.url_patterns:
                   ^^^^^^^^^^^^^^^^^
  File "C:\Python313\Lib\site-packages\django\utils\functional.py", line 57, in __get__
    res = instance.__dict__[self.name] = self.func(instance)
                                         ~~~~~~~~~^^^^^^^^^^
  File "C:\Python313\Lib\site-packages\django\urls\resolvers.py", line 715, in url_patterns
    patterns = getattr(self.urlconf_module, "urlpatterns", self.urlconf_module)
                       ^^^^^^^^^^^^^^^^^^^
  File "C:\Python313\Lib\site-packages\django\utils\functional.py", line 57, in __get__
    res = instance.__dict__[self.name] = self.func(instance)
                                         ~~~~~~~~~^^^^^^^^^^
  File "C:\Python313\Lib\site-packages\django\urls\resolvers.py", line 708, in urlconf_module
    return import_module(self.urlconf_name)
  File "C:\Python313\Lib\importlib\__init__.py", line 88, in import_module
    return _bootstrap._gcd_import(name[level:], package, level)
           ~~~~~~~~~~~~~~~~~~~~~~^^^^^^^^^^^^^^^^^^^^^^^^^^^^^^
  File "<frozen importlib._bootstrap>", line 1387, in _gcd_import
  File "<frozen importlib._bootstrap>", line 1360, in _find_and_load
  File "<frozen importlib._bootstrap>", line 1331, in _find_and_load_unlocked
  File "<frozen importlib._bootstrap>", line 935, in _load_unlocked
  File "<frozen importlib._bootstrap_external>", line 1022, in exec_module
  File "<frozen importlib._bootstrap>", line 488, in _call_with_frames_removed
  File "C:\inetpub\wwwroot\QueryManager\core\urls.py", line 24, in <module>
    re_path(r'^QueryManager/media/(?P<path>.*)$', serve,{'document_root': settings.MEDIA_ROOT}),
                                                  ^^^^^
NameError: name 'serve' is not defined
Performing system checks...

Exception in thread django-main-thread:
Traceback (most recent call last):
  File "C:\Python313\Lib\threading.py", line 1041, in _bootstrap_inner
    self.run()
    ~~~~~~~~^^
  File "C:\Python313\Lib\threading.py", line 992, in run
    self._target(*self._args, **self._kwargs)
    ~~~~~~~~~~~~^^^^^^^^^^^^^^^^^^^^^^^^^^^^^
  File "C:\Python313\Lib\site-packages\django\utils\autoreload.py", line 64, in wrapper
    fn(*args, **kwargs)
    ~~^^^^^^^^^^^^^^^^^
  File "C:\Python313\Lib\site-packages\django\core\management\commands\runserver.py", line 133, in inner_run
    self.check(display_num_errors=True)
    ~~~~~~~~~~^^^^^^^^^^^^^^^^^^^^^^^^^
  File "C:\Python313\Lib\site-packages\django\core\management\base.py", line 485, in check
    all_issues = checks.run_checks(
        app_configs=app_configs,
    ...<2 lines>...
        databases=databases,
    )
  File "C:\Python313\Lib\site-packages\django\core\checks\registry.py", line 88, in run_checks
    new_errors = check(app_configs=app_configs, databases=databases)
  File "C:\Python313\Lib\site-packages\django\core\checks\urls.py", line 14, in check_url_config
    return check_resolver(resolver)
  File "C:\Python313\Lib\site-packages\django\core\checks\urls.py", line 24, in check_resolver
    return check_method()
  File "C:\Python313\Lib\site-packages\django\urls\resolvers.py", line 494, in check
    for pattern in self.url_patterns:
                   ^^^^^^^^^^^^^^^^^
  File "C:\Python313\Lib\site-packages\django\utils\functional.py", line 57, in __get__
    res = instance.__dict__[self.name] = self.func(instance)
                                         ~~~~~~~~~^^^^^^^^^^
  File "C:\Python313\Lib\site-packages\django\urls\resolvers.py", line 715, in url_patterns
    patterns = getattr(self.urlconf_module, "urlpatterns", self.urlconf_module)
                       ^^^^^^^^^^^^^^^^^^^
  File "C:\Python313\Lib\site-packages\django\utils\functional.py", line 57, in __get__
    res = instance.__dict__[self.name] = self.func(instance)
                                         ~~~~~~~~~^^^^^^^^^^
  File "C:\Python313\Lib\site-packages\django\urls\resolvers.py", line 708, in urlconf_module
    return import_module(self.urlconf_name)
  File "C:\Python313\Lib\importlib\__init__.py", line 88, in import_module
    return _bootstrap._gcd_import(name[level:], package, level)
           ~~~~~~~~~~~~~~~~~~~~~~^^^^^^^^^^^^^^^^^^^^^^^^^^^^^^
  File "<frozen importlib._bootstrap>", line 1387, in _gcd_import
  File "<frozen importlib._bootstrap>", line 1360, in _find_and_load
  File "<frozen importlib._bootstrap>", line 1331, in _find_and_load_unlocked
  File "<frozen importlib._bootstrap>", line 935, in _load_unlocked
  File "<frozen importlib._bootstrap_external>", line 1022, in exec_module
  File "<frozen importlib._bootstrap>", line 488, in _call_with_frames_removed
  File "C:\inetpub\wwwroot\QueryManager\core\urls.py", line 27, in <module>
    ] + static(settings.STATIC_URL, document_root=settings.STATIC_ROOT) + \
        ^^^^^^
NameError: name 'static' is not defined
Performing system checks...

Exception in thread django-main-thread:
Traceback (most recent call last):
  File "C:\Python313\Lib\threading.py", line 1041, in _bootstrap_inner
    self.run()
    ~~~~~~~~^^
  File "C:\Python313\Lib\threading.py", line 992, in run
    self._target(*self._args, **self._kwargs)
    ~~~~~~~~~~~~^^^^^^^^^^^^^^^^^^^^^^^^^^^^^
  File "C:\Python313\Lib\site-packages\django\utils\autoreload.py", line 64, in wrapper
    fn(*args, **kwargs)
    ~~^^^^^^^^^^^^^^^^^
  File "C:\Python313\Lib\site-packages\django\core\management\commands\runserver.py", line 133, in inner_run
    self.check(display_num_errors=True)
    ~~~~~~~~~~^^^^^^^^^^^^^^^^^^^^^^^^^
  File "C:\Python313\Lib\site-packages\django\core\management\base.py", line 485, in check
    all_issues = checks.run_checks(
        app_configs=app_configs,
    ...<2 lines>...
        databases=databases,
    )
  File "C:\Python313\Lib\site-packages\django\core\checks\registry.py", line 88, in run_checks
    new_errors = check(app_configs=app_configs, databases=databases)
  File "C:\Python313\Lib\site-packages\django\core\checks\urls.py", line 14, in check_url_config
    return check_resolver(resolver)
  File "C:\Python313\Lib\site-packages\django\core\checks\urls.py", line 24, in check_resolver
    return check_method()
  File "C:\Python313\Lib\site-packages\django\urls\resolvers.py", line 494, in check
    for pattern in self.url_patterns:
                   ^^^^^^^^^^^^^^^^^
  File "C:\Python313\Lib\site-packages\django\utils\functional.py", line 57, in __get__
    res = instance.__dict__[self.name] = self.func(instance)
                                         ~~~~~~~~~^^^^^^^^^^
  File "C:\Python313\Lib\site-packages\django\urls\resolvers.py", line 715, in url_patterns
    patterns = getattr(self.urlconf_module, "urlpatterns", self.urlconf_module)
                       ^^^^^^^^^^^^^^^^^^^
  File "C:\Python313\Lib\site-packages\django\utils\functional.py", line 57, in __get__
    res = instance.__dict__[self.name] = self.func(instance)
                                         ~~~~~~~~~^^^^^^^^^^
  File "C:\Python313\Lib\site-packages\django\urls\resolvers.py", line 708, in urlconf_module
    return import_module(self.urlconf_name)
  File "C:\Python313\Lib\importlib\__init__.py", line 88, in import_module
    return _bootstrap._gcd_import(name[level:], package, level)
           ~~~~~~~~~~~~~~~~~~~~~~^^^^^^^^^^^^^^^^^^^^^^^^^^^^^^
  File "<frozen importlib._bootstrap>", line 1387, in _gcd_import
  File "<frozen importlib._bootstrap>", line 1360, in _find_and_load
  File "<frozen importlib._bootstrap>", line 1331, in _find_and_load_unlocked
  File "<frozen importlib._bootstrap>", line 935, in _load_unlocked
  File "<frozen importlib._bootstrap_external>", line 1022, in exec_module
  File "<frozen importlib._bootstrap>", line 488, in _call_with_frames_removed
  File "C:\inetpub\wwwroot\QueryManager\core\urls.py", line 27, in <module>
    ] + static(settings.STATIC_URL, document_root=settings.STATIC_ROOT) + \
        ^^^^^^
NameError: name 'static' is not defined
Performing system checks...

Exception in thread django-main-thread:
Traceback (most recent call last):
  File "C:\Python313\Lib\threading.py", line 1041, in _bootstrap_inner
    self.run()
    ~~~~~~~~^^
  File "C:\Python313\Lib\threading.py", line 992, in run
    self._target(*self._args, **self._kwargs)
    ~~~~~~~~~~~~^^^^^^^^^^^^^^^^^^^^^^^^^^^^^
  File "C:\Python313\Lib\site-packages\django\utils\autoreload.py", line 64, in wrapper
    fn(*args, **kwargs)
    ~~^^^^^^^^^^^^^^^^^
  File "C:\Python313\Lib\site-packages\django\core\management\commands\runserver.py", line 133, in inner_run
    self.check(display_num_errors=True)
    ~~~~~~~~~~^^^^^^^^^^^^^^^^^^^^^^^^^
  File "C:\Python313\Lib\site-packages\django\core\management\base.py", line 485, in check
    all_issues = checks.run_checks(
        app_configs=app_configs,
    ...<2 lines>...
        databases=databases,
    )
  File "C:\Python313\Lib\site-packages\django\core\checks\registry.py", line 88, in run_checks
    new_errors = check(app_configs=app_configs, databases=databases)
  File "C:\Python313\Lib\site-packages\django\core\checks\urls.py", line 14, in check_url_config
    return check_resolver(resolver)
  File "C:\Python313\Lib\site-packages\django\core\checks\urls.py", line 24, in check_resolver
    return check_method()
  File "C:\Python313\Lib\site-packages\django\urls\resolvers.py", line 494, in check
    for pattern in self.url_patterns:
                   ^^^^^^^^^^^^^^^^^
  File "C:\Python313\Lib\site-packages\django\utils\functional.py", line 57, in __get__
    res = instance.__dict__[self.name] = self.func(instance)
                                         ~~~~~~~~~^^^^^^^^^^
  File "C:\Python313\Lib\site-packages\django\urls\resolvers.py", line 715, in url_patterns
    patterns = getattr(self.urlconf_module, "urlpatterns", self.urlconf_module)
                       ^^^^^^^^^^^^^^^^^^^
  File "C:\Python313\Lib\site-packages\django\utils\functional.py", line 57, in __get__
    res = instance.__dict__[self.name] = self.func(instance)
                                         ~~~~~~~~~^^^^^^^^^^
  File "C:\Python313\Lib\site-packages\django\urls\resolvers.py", line 708, in urlconf_module
    return import_module(self.urlconf_name)
  File "C:\Python313\Lib\importlib\__init__.py", line 88, in import_module
    return _bootstrap._gcd_import(name[level:], package, level)
           ~~~~~~~~~~~~~~~~~~~~~~^^^^^^^^^^^^^^^^^^^^^^^^^^^^^^
  File "<frozen importlib._bootstrap>", line 1387, in _gcd_import
  File "<frozen importlib._bootstrap>", line 1360, in _find_and_load
  File "<frozen importlib._bootstrap>", line 1331, in _find_and_load_unlocked
  File "<frozen importlib._bootstrap>", line 935, in _load_unlocked
  File "<frozen importlib._bootstrap_external>", line 1022, in exec_module
  File "<frozen importlib._bootstrap>", line 488, in _call_with_frames_removed
  File "C:\inetpub\wwwroot\QueryManager\core\urls.py", line 27, in <module>
    ] + static(settings.STATIC_URL, document_root=settings.STATIC_ROOT) + \
        ^^^^^^
NameError: name 'static' is not defined
Performing system checks...

Exception in thread django-main-thread:
Traceback (most recent call last):
  File "C:\Python313\Lib\threading.py", line 1041, in _bootstrap_inner
    self.run()
    ~~~~~~~~^^
  File "C:\Python313\Lib\threading.py", line 992, in run
    self._target(*self._args, **self._kwargs)
    ~~~~~~~~~~~~^^^^^^^^^^^^^^^^^^^^^^^^^^^^^
  File "C:\Python313\Lib\site-packages\django\utils\autoreload.py", line 64, in wrapper
    fn(*args, **kwargs)
    ~~^^^^^^^^^^^^^^^^^
  File "C:\Python313\Lib\site-packages\django\core\management\commands\runserver.py", line 133, in inner_run
    self.check(display_num_errors=True)
    ~~~~~~~~~~^^^^^^^^^^^^^^^^^^^^^^^^^
  File "C:\Python313\Lib\site-packages\django\core\management\base.py", line 485, in check
    all_issues = checks.run_checks(
        app_configs=app_configs,
    ...<2 lines>...
        databases=databases,
    )
  File "C:\Python313\Lib\site-packages\django\core\checks\registry.py", line 88, in run_checks
    new_errors = check(app_configs=app_configs, databases=databases)
  File "C:\Python313\Lib\site-packages\django\core\checks\urls.py", line 14, in check_url_config
    return check_resolver(resolver)
  File "C:\Python313\Lib\site-packages\django\core\checks\urls.py", line 24, in check_resolver
    return check_method()
  File "C:\Python313\Lib\site-packages\django\urls\resolvers.py", line 494, in check
    for pattern in self.url_patterns:
                   ^^^^^^^^^^^^^^^^^
  File "C:\Python313\Lib\site-packages\django\utils\functional.py", line 57, in __get__
    res = instance.__dict__[self.name] = self.func(instance)
                                         ~~~~~~~~~^^^^^^^^^^
  File "C:\Python313\Lib\site-packages\django\urls\resolvers.py", line 715, in url_patterns
    patterns = getattr(self.urlconf_module, "urlpatterns", self.urlconf_module)
                       ^^^^^^^^^^^^^^^^^^^
  File "C:\Python313\Lib\site-packages\django\utils\functional.py", line 57, in __get__
    res = instance.__dict__[self.name] = self.func(instance)
                                         ~~~~~~~~~^^^^^^^^^^
  File "C:\Python313\Lib\site-packages\django\urls\resolvers.py", line 708, in urlconf_module
    return import_module(self.urlconf_name)
  File "C:\Python313\Lib\importlib\__init__.py", line 88, in import_module
    return _bootstrap._gcd_import(name[level:], package, level)
           ~~~~~~~~~~~~~~~~~~~~~~^^^^^^^^^^^^^^^^^^^^^^^^^^^^^^
  File "<frozen importlib._bootstrap>", line 1387, in _gcd_import
  File "<frozen importlib._bootstrap>", line 1360, in _find_and_load
  File "<frozen importlib._bootstrap>", line 1331, in _find_and_load_unlocked
  File "<frozen importlib._bootstrap>", line 935, in _load_unlocked
  File "<frozen importlib._bootstrap_external>", line 1022, in exec_module
  File "<frozen importlib._bootstrap>", line 488, in _call_with_frames_removed
  File "C:\inetpub\wwwroot\QueryManager\core\urls.py", line 23, in <module>
    path('',include('main.urls')),
            ~~~~~~~^^^^^^^^^^^^^
  File "C:\Python313\Lib\site-packages\django\urls\conf.py", line 38, in include
    urlconf_module = import_module(urlconf_module)
  File "C:\Python313\Lib\importlib\__init__.py", line 88, in import_module
    return _bootstrap._gcd_import(name[level:], package, level)
           ~~~~~~~~~~~~~~~~~~~~~~^^^^^^^^^^^^^^^^^^^^^^^^^^^^^^
  File "<frozen importlib._bootstrap>", line 1387, in _gcd_import
  File "<frozen importlib._bootstrap>", line 1360, in _find_and_load
  File "<frozen importlib._bootstrap>", line 1331, in _find_and_load_unlocked
  File "<frozen importlib._bootstrap>", line 935, in _load_unlocked
  File "<frozen importlib._bootstrap_external>", line 1022, in exec_module
  File "<frozen importlib._bootstrap>", line 488, in _call_with_frames_removed
  File "C:\inetpub\wwwroot\QueryManager\main\urls.py", line 29, in <module>
    re_path(r'^QueryManager/media/(?P<path>.*)$', serve,{'document_root': settings.MEDIA_ROOT}),
    ^^^^^^^
NameError: name 're_path' is not defined
Performing system checks...

Exception in thread django-main-thread:
Traceback (most recent call last):
  File "C:\Python313\Lib\threading.py", line 1041, in _bootstrap_inner
    self.run()
    ~~~~~~~~^^
  File "C:\Python313\Lib\threading.py", line 992, in run
    self._target(*self._args, **self._kwargs)
    ~~~~~~~~~~~~^^^^^^^^^^^^^^^^^^^^^^^^^^^^^
  File "C:\Python313\Lib\site-packages\django\utils\autoreload.py", line 64, in wrapper
    fn(*args, **kwargs)
    ~~^^^^^^^^^^^^^^^^^
  File "C:\Python313\Lib\site-packages\django\core\management\commands\runserver.py", line 133, in inner_run
    self.check(display_num_errors=True)
    ~~~~~~~~~~^^^^^^^^^^^^^^^^^^^^^^^^^
  File "C:\Python313\Lib\site-packages\django\core\management\base.py", line 485, in check
    all_issues = checks.run_checks(
        app_configs=app_configs,
    ...<2 lines>...
        databases=databases,
    )
  File "C:\Python313\Lib\site-packages\django\core\checks\registry.py", line 88, in run_checks
    new_errors = check(app_configs=app_configs, databases=databases)
  File "C:\Python313\Lib\site-packages\django\core\checks\urls.py", line 14, in check_url_config
    return check_resolver(resolver)
  File "C:\Python313\Lib\site-packages\django\core\checks\urls.py", line 24, in check_resolver
    return check_method()
  File "C:\Python313\Lib\site-packages\django\urls\resolvers.py", line 494, in check
    for pattern in self.url_patterns:
                   ^^^^^^^^^^^^^^^^^
  File "C:\Python313\Lib\site-packages\django\utils\functional.py", line 57, in __get__
    res = instance.__dict__[self.name] = self.func(instance)
                                         ~~~~~~~~~^^^^^^^^^^
  File "C:\Python313\Lib\site-packages\django\urls\resolvers.py", line 715, in url_patterns
    patterns = getattr(self.urlconf_module, "urlpatterns", self.urlconf_module)
                       ^^^^^^^^^^^^^^^^^^^
  File "C:\Python313\Lib\site-packages\django\utils\functional.py", line 57, in __get__
    res = instance.__dict__[self.name] = self.func(instance)
                                         ~~~~~~~~~^^^^^^^^^^
  File "C:\Python313\Lib\site-packages\django\urls\resolvers.py", line 708, in urlconf_module
    return import_module(self.urlconf_name)
  File "C:\Python313\Lib\importlib\__init__.py", line 88, in import_module
    return _bootstrap._gcd_import(name[level:], package, level)
           ~~~~~~~~~~~~~~~~~~~~~~^^^^^^^^^^^^^^^^^^^^^^^^^^^^^^
  File "<frozen importlib._bootstrap>", line 1387, in _gcd_import
  File "<frozen importlib._bootstrap>", line 1360, in _find_and_load
  File "<frozen importlib._bootstrap>", line 1331, in _find_and_load_unlocked
  File "<frozen importlib._bootstrap>", line 935, in _load_unlocked
  File "<frozen importlib._bootstrap_external>", line 1022, in exec_module
  File "<frozen importlib._bootstrap>", line 488, in _call_with_frames_removed
  File "C:\inetpub\wwwroot\QueryManager\core\urls.py", line 23, in <module>
    path('',include('main.urls')),
            ~~~~~~~^^^^^^^^^^^^^
  File "C:\Python313\Lib\site-packages\django\urls\conf.py", line 38, in include
    urlconf_module = import_module(urlconf_module)
  File "C:\Python313\Lib\importlib\__init__.py", line 88, in import_module
    return _bootstrap._gcd_import(name[level:], package, level)
           ~~~~~~~~~~~~~~~~~~~~~~^^^^^^^^^^^^^^^^^^^^^^^^^^^^^^
  File "<frozen importlib._bootstrap>", line 1387, in _gcd_import
  File "<frozen importlib._bootstrap>", line 1360, in _find_and_load
  File "<frozen importlib._bootstrap>", line 1331, in _find_and_load_unlocked
  File "<frozen importlib._bootstrap>", line 935, in _load_unlocked
  File "<frozen importlib._bootstrap_external>", line 1022, in exec_module
  File "<frozen importlib._bootstrap>", line 488, in _call_with_frames_removed
  File "C:\inetpub\wwwroot\QueryManager\main\urls.py", line 29, in <module>
    re_path(r'^QueryManager/media/(?P<path>.*)$', serve,{'document_root': settings.MEDIA_ROOT}),
    ^^^^^^^
NameError: name 're_path' is not defined
Performing system checks...

[17/Nov/2024 21:45:08] "GET /QueryManager/ HTTP/1.1" 200 13035
[17/Nov/2024 21:45:08] "GET /QueryManager/static/bootstrap.min.css HTTP/1.1" 404 179
[17/Nov/2024 21:45:08] "GET /QueryManager/static/custom.css HTTP/1.1" 404 179
[17/Nov/2024 21:45:08] "GET /QueryManager/static/profile_pics/default2.jpg HTTP/1.1" 404 179
[17/Nov/2024 21:45:08] "GET /QueryManager/static/query_manager.png HTTP/1.1" 404 179
Performing system checks...

System check identified no issues (0 silenced).
November 17, 2024 - 21:45:07
Django version 4.2.16, using settings 'core.settings'
Starting development server at http://127.0.0.1:22915/
Quit the server with CTRL-BREAK.

Exception in thread django-main-thread:
Traceback (most recent call last):
  File "C:\Python313\Lib\threading.py", line 1041, in _bootstrap_inner
    self.run()
    ~~~~~~~~^^
  File "C:\Python313\Lib\threading.py", line 992, in run
    self._target(*self._args, **self._kwargs)
    ~~~~~~~~~~~~^^^^^^^^^^^^^^^^^^^^^^^^^^^^^
  File "C:\Python313\Lib\site-packages\django\utils\autoreload.py", line 64, in wrapper
    fn(*args, **kwargs)
    ~~^^^^^^^^^^^^^^^^^
  File "C:\Python313\Lib\site-packages\django\core\management\commands\runserver.py", line 133, in inner_run
    self.check(display_num_errors=True)
    ~~~~~~~~~~^^^^^^^^^^^^^^^^^^^^^^^^^
  File "C:\Python313\Lib\site-packages\django\core\management\base.py", line 485, in check
    all_issues = checks.run_checks(
        app_configs=app_configs,
    ...<2 lines>...
        databases=databases,
    )
  File "C:\Python313\Lib\site-packages\django\core\checks\registry.py", line 88, in run_checks
    new_errors = check(app_configs=app_configs, databases=databases)
  File "C:\Python313\Lib\site-packages\django\core\checks\urls.py", line 14, in check_url_config
    return check_resolver(resolver)
  File "C:\Python313\Lib\site-packages\django\core\checks\urls.py", line 24, in check_resolver
    return check_method()
  File "C:\Python313\Lib\site-packages\django\urls\resolvers.py", line 494, in check
    for pattern in self.url_patterns:
                   ^^^^^^^^^^^^^^^^^
  File "C:\Python313\Lib\site-packages\django\utils\functional.py", line 57, in __get__
    res = instance.__dict__[self.name] = self.func(instance)
                                         ~~~~~~~~~^^^^^^^^^^
  File "C:\Python313\Lib\site-packages\django\urls\resolvers.py", line 715, in url_patterns
    patterns = getattr(self.urlconf_module, "urlpatterns", self.urlconf_module)
                       ^^^^^^^^^^^^^^^^^^^
  File "C:\Python313\Lib\site-packages\django\utils\functional.py", line 57, in __get__
    res = instance.__dict__[self.name] = self.func(instance)
                                         ~~~~~~~~~^^^^^^^^^^
  File "C:\Python313\Lib\site-packages\django\urls\resolvers.py", line 708, in urlconf_module
    return import_module(self.urlconf_name)
  File "C:\Python313\Lib\importlib\__init__.py", line 88, in import_module
    return _bootstrap._gcd_import(name[level:], package, level)
           ~~~~~~~~~~~~~~~~~~~~~~^^^^^^^^^^^^^^^^^^^^^^^^^^^^^^
  File "<frozen importlib._bootstrap>", line 1387, in _gcd_import
  File "<frozen importlib._bootstrap>", line 1360, in _find_and_load
  File "<frozen importlib._bootstrap>", line 1331, in _find_and_load_unlocked
  File "<frozen importlib._bootstrap>", line 935, in _load_unlocked
  File "<frozen importlib._bootstrap_external>", line 1022, in exec_module
  File "<frozen importlib._bootstrap>", line 488, in _call_with_frames_removed
  File "C:\inetpub\wwwroot\QueryManager\core\urls.py", line 21, in <module>
    path('',include('main.urls')),
            ~~~~~~~^^^^^^^^^^^^^
  File "C:\Python313\Lib\site-packages\django\urls\conf.py", line 38, in include
    urlconf_module = import_module(urlconf_module)
  File "C:\Python313\Lib\importlib\__init__.py", line 88, in import_module
    return _bootstrap._gcd_import(name[level:], package, level)
           ~~~~~~~~~~~~~~~~~~~~~~^^^^^^^^^^^^^^^^^^^^^^^^^^^^^^
  File "<frozen importlib._bootstrap>", line 1387, in _gcd_import
  File "<frozen importlib._bootstrap>", line 1360, in _find_and_load
  File "<frozen importlib._bootstrap>", line 1331, in _find_and_load_unlocked
  File "<frozen importlib._bootstrap>", line 935, in _load_unlocked
  File "<frozen importlib._bootstrap_external>", line 1022, in exec_module
  File "<frozen importlib._bootstrap>", line 488, in _call_with_frames_removed
  File "C:\inetpub\wwwroot\QueryManager\main\urls.py", line 29, in <module>
    re_path(r'^QueryManager/media/(?P<path>.*)$', serve,{'document_root': settings.MEDIA_ROOT}),
                                                  ^^^^^
NameError: name 'serve' is not defined
Performing system checks...

Exception in thread django-main-thread:
Traceback (most recent call last):
  File "C:\Python313\Lib\threading.py", line 1041, in _bootstrap_inner
    self.run()
    ~~~~~~~~^^
  File "C:\Python313\Lib\threading.py", line 992, in run
    self._target(*self._args, **self._kwargs)
    ~~~~~~~~~~~~^^^^^^^^^^^^^^^^^^^^^^^^^^^^^
  File "C:\Python313\Lib\site-packages\django\utils\autoreload.py", line 64, in wrapper
    fn(*args, **kwargs)
    ~~^^^^^^^^^^^^^^^^^
  File "C:\Python313\Lib\site-packages\django\core\management\commands\runserver.py", line 133, in inner_run
    self.check(display_num_errors=True)
    ~~~~~~~~~~^^^^^^^^^^^^^^^^^^^^^^^^^
  File "C:\Python313\Lib\site-packages\django\core\management\base.py", line 485, in check
    all_issues = checks.run_checks(
        app_configs=app_configs,
    ...<2 lines>...
        databases=databases,
    )
  File "C:\Python313\Lib\site-packages\django\core\checks\registry.py", line 88, in run_checks
    new_errors = check(app_configs=app_configs, databases=databases)
  File "C:\Python313\Lib\site-packages\django\core\checks\urls.py", line 14, in check_url_config
    return check_resolver(resolver)
  File "C:\Python313\Lib\site-packages\django\core\checks\urls.py", line 24, in check_resolver
    return check_method()
  File "C:\Python313\Lib\site-packages\django\urls\resolvers.py", line 494, in check
    for pattern in self.url_patterns:
                   ^^^^^^^^^^^^^^^^^
  File "C:\Python313\Lib\site-packages\django\utils\functional.py", line 57, in __get__
    res = instance.__dict__[self.name] = self.func(instance)
                                         ~~~~~~~~~^^^^^^^^^^
  File "C:\Python313\Lib\site-packages\django\urls\resolvers.py", line 715, in url_patterns
    patterns = getattr(self.urlconf_module, "urlpatterns", self.urlconf_module)
                       ^^^^^^^^^^^^^^^^^^^
  File "C:\Python313\Lib\site-packages\django\utils\functional.py", line 57, in __get__
    res = instance.__dict__[self.name] = self.func(instance)
                                         ~~~~~~~~~^^^^^^^^^^
  File "C:\Python313\Lib\site-packages\django\urls\resolvers.py", line 708, in urlconf_module
    return import_module(self.urlconf_name)
  File "C:\Python313\Lib\importlib\__init__.py", line 88, in import_module
    return _bootstrap._gcd_import(name[level:], package, level)
           ~~~~~~~~~~~~~~~~~~~~~~^^^^^^^^^^^^^^^^^^^^^^^^^^^^^^
  File "<frozen importlib._bootstrap>", line 1387, in _gcd_import
  File "<frozen importlib._bootstrap>", line 1360, in _find_and_load
  File "<frozen importlib._bootstrap>", line 1331, in _find_and_load_unlocked
  File "<frozen importlib._bootstrap>", line 935, in _load_unlocked
  File "<frozen importlib._bootstrap_external>", line 1022, in exec_module
  File "<frozen importlib._bootstrap>", line 488, in _call_with_frames_removed
  File "C:\inetpub\wwwroot\QueryManager\core\urls.py", line 21, in <module>
    path('',include('main.urls')),
            ~~~~~~~^^^^^^^^^^^^^
  File "C:\Python313\Lib\site-packages\django\urls\conf.py", line 38, in include
    urlconf_module = import_module(urlconf_module)
  File "C:\Python313\Lib\importlib\__init__.py", line 88, in import_module
    return _bootstrap._gcd_import(name[level:], package, level)
           ~~~~~~~~~~~~~~~~~~~~~~^^^^^^^^^^^^^^^^^^^^^^^^^^^^^^
  File "<frozen importlib._bootstrap>", line 1387, in _gcd_import
  File "<frozen importlib._bootstrap>", line 1360, in _find_and_load
  File "<frozen importlib._bootstrap>", line 1331, in _find_and_load_unlocked
  File "<frozen importlib._bootstrap>", line 935, in _load_unlocked
  File "<frozen importlib._bootstrap_external>", line 1022, in exec_module
  File "<frozen importlib._bootstrap>", line 488, in _call_with_frames_removed
  File "C:\inetpub\wwwroot\QueryManager\main\urls.py", line 29, in <module>
    re_path(r'^QueryManager/media/(?P<path>.*)$', serve,{'document_root': settings.MEDIA_ROOT}),
                                                  ^^^^^
NameError: name 'serve' is not defined
Performing system checks...

Performing system checks...

System check identified no issues (0 silenced).
November 17, 2024 - 21:46:56
Django version 4.2.16, using settings 'core.settings'
Starting development server at http://127.0.0.1:22915/
Quit the server with CTRL-BREAK.

[17/Nov/2024 21:47:01] "GET /QueryManager/ HTTP/1.1" 200 13035
[17/Nov/2024 21:47:01] "GET /QueryManager/static/bootstrap.min.css HTTP/1.1" 404 179
[17/Nov/2024 21:47:01] "GET /QueryManager/static/custom.css HTTP/1.1" 404 179
[17/Nov/2024 21:47:01] "GET /QueryManager/static/profile_pics/default2.jpg HTTP/1.1" 404 179
[17/Nov/2024 21:47:01] "GET /QueryManager/static/query_manager.png HTTP/1.1" 404 179
Performing system checks...

System check identified no issues (0 silenced).
November 17, 2024 - 21:47:01
Django version 4.2.16, using settings 'core.settings'
Starting development server at http://127.0.0.1:22915/
Quit the server with CTRL-BREAK.

Performing system checks...

System check identified no issues (0 silenced).
November 17, 2024 - 21:47:28
Django version 4.2.16, using settings 'core.settings'
Starting development server at http://127.0.0.1:22915/
Quit the server with CTRL-BREAK.

Exception in thread django-main-thread:
Traceback (most recent call last):
  File "C:\Python313\Lib\threading.py", line 1041, in _bootstrap_inner
    self.run()
    ~~~~~~~~^^
  File "C:\Python313\Lib\threading.py", line 992, in run
    self._target(*self._args, **self._kwargs)
    ~~~~~~~~~~~~^^^^^^^^^^^^^^^^^^^^^^^^^^^^^
  File "C:\Python313\Lib\site-packages\django\utils\autoreload.py", line 64, in wrapper
    fn(*args, **kwargs)
    ~~^^^^^^^^^^^^^^^^^
  File "C:\Python313\Lib\site-packages\django\core\management\commands\runserver.py", line 133, in inner_run
    self.check(display_num_errors=True)
    ~~~~~~~~~~^^^^^^^^^^^^^^^^^^^^^^^^^
  File "C:\Python313\Lib\site-packages\django\core\management\base.py", line 485, in check
    all_issues = checks.run_checks(
        app_configs=app_configs,
    ...<2 lines>...
        databases=databases,
    )
  File "C:\Python313\Lib\site-packages\django\core\checks\registry.py", line 88, in run_checks
    new_errors = check(app_configs=app_configs, databases=databases)
  File "C:\Python313\Lib\site-packages\django\core\checks\urls.py", line 14, in check_url_config
    return check_resolver(resolver)
  File "C:\Python313\Lib\site-packages\django\core\checks\urls.py", line 24, in check_resolver
    return check_method()
  File "C:\Python313\Lib\site-packages\django\urls\resolvers.py", line 494, in check
    for pattern in self.url_patterns:
                   ^^^^^^^^^^^^^^^^^
  File "C:\Python313\Lib\site-packages\django\utils\functional.py", line 57, in __get__
    res = instance.__dict__[self.name] = self.func(instance)
                                         ~~~~~~~~~^^^^^^^^^^
  File "C:\Python313\Lib\site-packages\django\urls\resolvers.py", line 715, in url_patterns
    patterns = getattr(self.urlconf_module, "urlpatterns", self.urlconf_module)
                       ^^^^^^^^^^^^^^^^^^^
  File "C:\Python313\Lib\site-packages\django\utils\functional.py", line 57, in __get__
    res = instance.__dict__[self.name] = self.func(instance)
                                         ~~~~~~~~~^^^^^^^^^^
  File "C:\Python313\Lib\site-packages\django\urls\resolvers.py", line 708, in urlconf_module
    return import_module(self.urlconf_name)
  File "C:\Python313\Lib\importlib\__init__.py", line 88, in import_module
    return _bootstrap._gcd_import(name[level:], package, level)
           ~~~~~~~~~~~~~~~~~~~~~~^^^^^^^^^^^^^^^^^^^^^^^^^^^^^^
  File "<frozen importlib._bootstrap>", line 1387, in _gcd_import
  File "<frozen importlib._bootstrap>", line 1360, in _find_and_load
  File "<frozen importlib._bootstrap>", line 1331, in _find_and_load_unlocked
  File "<frozen importlib._bootstrap>", line 935, in _load_unlocked
  File "<frozen importlib._bootstrap_external>", line 1022, in exec_module
  File "<frozen importlib._bootstrap>", line 488, in _call_with_frames_removed
  File "C:\inetpub\wwwroot\QueryManager\core\urls.py", line 23, in <module>
    re_path(r'^media/(?P<path>.*)$', serve,{'document_root': settings.MEDIA_ROOT}),
                                     ^^^^^
NameError: name 'serve' is not defined
Performing system checks...

Exception in thread django-main-thread:
Traceback (most recent call last):
  File "C:\Python313\Lib\threading.py", line 1041, in _bootstrap_inner
    self.run()
    ~~~~~~~~^^
  File "C:\Python313\Lib\threading.py", line 992, in run
    self._target(*self._args, **self._kwargs)
    ~~~~~~~~~~~~^^^^^^^^^^^^^^^^^^^^^^^^^^^^^
  File "C:\Python313\Lib\site-packages\django\utils\autoreload.py", line 64, in wrapper
    fn(*args, **kwargs)
    ~~^^^^^^^^^^^^^^^^^
  File "C:\Python313\Lib\site-packages\django\core\management\commands\runserver.py", line 133, in inner_run
    self.check(display_num_errors=True)
    ~~~~~~~~~~^^^^^^^^^^^^^^^^^^^^^^^^^
  File "C:\Python313\Lib\site-packages\django\core\management\base.py", line 485, in check
    all_issues = checks.run_checks(
        app_configs=app_configs,
    ...<2 lines>...
        databases=databases,
    )
  File "C:\Python313\Lib\site-packages\django\core\checks\registry.py", line 88, in run_checks
    new_errors = check(app_configs=app_configs, databases=databases)
  File "C:\Python313\Lib\site-packages\django\core\checks\urls.py", line 14, in check_url_config
    return check_resolver(resolver)
  File "C:\Python313\Lib\site-packages\django\core\checks\urls.py", line 24, in check_resolver
    return check_method()
  File "C:\Python313\Lib\site-packages\django\urls\resolvers.py", line 494, in check
    for pattern in self.url_patterns:
                   ^^^^^^^^^^^^^^^^^
  File "C:\Python313\Lib\site-packages\django\utils\functional.py", line 57, in __get__
    res = instance.__dict__[self.name] = self.func(instance)
                                         ~~~~~~~~~^^^^^^^^^^
  File "C:\Python313\Lib\site-packages\django\urls\resolvers.py", line 715, in url_patterns
    patterns = getattr(self.urlconf_module, "urlpatterns", self.urlconf_module)
                       ^^^^^^^^^^^^^^^^^^^
  File "C:\Python313\Lib\site-packages\django\utils\functional.py", line 57, in __get__
    res = instance.__dict__[self.name] = self.func(instance)
                                         ~~~~~~~~~^^^^^^^^^^
  File "C:\Python313\Lib\site-packages\django\urls\resolvers.py", line 708, in urlconf_module
    return import_module(self.urlconf_name)
  File "C:\Python313\Lib\importlib\__init__.py", line 88, in import_module
    return _bootstrap._gcd_import(name[level:], package, level)
           ~~~~~~~~~~~~~~~~~~~~~~^^^^^^^^^^^^^^^^^^^^^^^^^^^^^^
  File "<frozen importlib._bootstrap>", line 1387, in _gcd_import
  File "<frozen importlib._bootstrap>", line 1360, in _find_and_load
  File "<frozen importlib._bootstrap>", line 1331, in _find_and_load_unlocked
  File "<frozen importlib._bootstrap>", line 935, in _load_unlocked
  File "<frozen importlib._bootstrap_external>", line 1022, in exec_module
  File "<frozen importlib._bootstrap>", line 488, in _call_with_frames_removed
  File "C:\inetpub\wwwroot\QueryManager\core\urls.py", line 24, in <module>
    re_path(r'^media/(?P<path>.*)$', serve,{'document_root': settings.MEDIA_ROOT}),
                                     ^^^^^
NameError: name 'serve' is not defined
Performing system checks...

Exception in thread django-main-thread:
Traceback (most recent call last):
  File "C:\Python313\Lib\threading.py", line 1041, in _bootstrap_inner
    self.run()
    ~~~~~~~~^^
  File "C:\Python313\Lib\threading.py", line 992, in run
    self._target(*self._args, **self._kwargs)
    ~~~~~~~~~~~~^^^^^^^^^^^^^^^^^^^^^^^^^^^^^
  File "C:\Python313\Lib\site-packages\django\utils\autoreload.py", line 64, in wrapper
    fn(*args, **kwargs)
    ~~^^^^^^^^^^^^^^^^^
  File "C:\Python313\Lib\site-packages\django\core\management\commands\runserver.py", line 133, in inner_run
    self.check(display_num_errors=True)
    ~~~~~~~~~~^^^^^^^^^^^^^^^^^^^^^^^^^
  File "C:\Python313\Lib\site-packages\django\core\management\base.py", line 485, in check
    all_issues = checks.run_checks(
        app_configs=app_configs,
    ...<2 lines>...
        databases=databases,
    )
  File "C:\Python313\Lib\site-packages\django\core\checks\registry.py", line 88, in run_checks
    new_errors = check(app_configs=app_configs, databases=databases)
  File "C:\Python313\Lib\site-packages\django\core\checks\urls.py", line 14, in check_url_config
    return check_resolver(resolver)
  File "C:\Python313\Lib\site-packages\django\core\checks\urls.py", line 24, in check_resolver
    return check_method()
  File "C:\Python313\Lib\site-packages\django\urls\resolvers.py", line 494, in check
    for pattern in self.url_patterns:
                   ^^^^^^^^^^^^^^^^^
  File "C:\Python313\Lib\site-packages\django\utils\functional.py", line 57, in __get__
    res = instance.__dict__[self.name] = self.func(instance)
                                         ~~~~~~~~~^^^^^^^^^^
  File "C:\Python313\Lib\site-packages\django\urls\resolvers.py", line 715, in url_patterns
    patterns = getattr(self.urlconf_module, "urlpatterns", self.urlconf_module)
                       ^^^^^^^^^^^^^^^^^^^
  File "C:\Python313\Lib\site-packages\django\utils\functional.py", line 57, in __get__
    res = instance.__dict__[self.name] = self.func(instance)
                                         ~~~~~~~~~^^^^^^^^^^
  File "C:\Python313\Lib\site-packages\django\urls\resolvers.py", line 708, in urlconf_module
    return import_module(self.urlconf_name)
  File "C:\Python313\Lib\importlib\__init__.py", line 88, in import_module
    return _bootstrap._gcd_import(name[level:], package, level)
           ~~~~~~~~~~~~~~~~~~~~~~^^^^^^^^^^^^^^^^^^^^^^^^^^^^^^
  File "<frozen importlib._bootstrap>", line 1387, in _gcd_import
  File "<frozen importlib._bootstrap>", line 1360, in _find_and_load
  File "<frozen importlib._bootstrap>", line 1331, in _find_and_load_unlocked
  File "<frozen importlib._bootstrap>", line 935, in _load_unlocked
  File "<frozen importlib._bootstrap_external>", line 1022, in exec_module
  File "<frozen importlib._bootstrap>", line 488, in _call_with_frames_removed
  File "C:\inetpub\wwwroot\QueryManager\core\urls.py", line 24, in <module>
    re_path(r'^media/(?P<path>.*)$', serve,{'document_root': settings.MEDIA_ROOT}),
                                     ^^^^^
NameError: name 'serve' is not defined
Performing system checks...

[17/Nov/2024 21:49:54] "GET /QueryManager/ HTTP/1.1" 200 13035
[17/Nov/2024 21:49:54] "GET /QueryManager/static/bootstrap.min.css HTTP/1.1" 404 179
[17/Nov/2024 21:49:54] "GET /QueryManager/static/query_manager.png HTTP/1.1" 404 179
[17/Nov/2024 21:49:54] "GET /QueryManager/static/custom.css HTTP/1.1" 404 179
[17/Nov/2024 21:49:54] "GET /QueryManager/static/profile_pics/default2.jpg HTTP/1.1" 404 179
Performing system checks...

System check identified no issues (0 silenced).
November 17, 2024 - 21:49:49
Django version 4.2.16, using settings 'core.settings'
Starting development server at http://127.0.0.1:22915/
Quit the server with CTRL-BREAK.

Performing system checks...

System check identified no issues (0 silenced).
November 17, 2024 - 21:50:15
Django version 4.2.16, using settings 'core.settings'
Starting development server at http://127.0.0.1:22915/
Quit the server with CTRL-BREAK.

Exception in thread django-main-thread:
Traceback (most recent call last):
  File "C:\Python313\Lib\threading.py", line 1041, in _bootstrap_inner
    self.run()
    ~~~~~~~~^^
  File "C:\Python313\Lib\threading.py", line 992, in run
    self._target(*self._args, **self._kwargs)
    ~~~~~~~~~~~~^^^^^^^^^^^^^^^^^^^^^^^^^^^^^
  File "C:\Python313\Lib\site-packages\django\utils\autoreload.py", line 64, in wrapper
    fn(*args, **kwargs)
    ~~^^^^^^^^^^^^^^^^^
  File "C:\Python313\Lib\site-packages\django\core\management\commands\runserver.py", line 133, in inner_run
    self.check(display_num_errors=True)
    ~~~~~~~~~~^^^^^^^^^^^^^^^^^^^^^^^^^
  File "C:\Python313\Lib\site-packages\django\core\management\base.py", line 485, in check
    all_issues = checks.run_checks(
        app_configs=app_configs,
    ...<2 lines>...
        databases=databases,
    )
  File "C:\Python313\Lib\site-packages\django\core\checks\registry.py", line 88, in run_checks
    new_errors = check(app_configs=app_configs, databases=databases)
  File "C:\Python313\Lib\site-packages\django\core\checks\urls.py", line 14, in check_url_config
    return check_resolver(resolver)
  File "C:\Python313\Lib\site-packages\django\core\checks\urls.py", line 24, in check_resolver
    return check_method()
  File "C:\Python313\Lib\site-packages\django\urls\resolvers.py", line 494, in check
    for pattern in self.url_patterns:
                   ^^^^^^^^^^^^^^^^^
  File "C:\Python313\Lib\site-packages\django\utils\functional.py", line 57, in __get__
    res = instance.__dict__[self.name] = self.func(instance)
                                         ~~~~~~~~~^^^^^^^^^^
  File "C:\Python313\Lib\site-packages\django\urls\resolvers.py", line 715, in url_patterns
    patterns = getattr(self.urlconf_module, "urlpatterns", self.urlconf_module)
                       ^^^^^^^^^^^^^^^^^^^
  File "C:\Python313\Lib\site-packages\django\utils\functional.py", line 57, in __get__
    res = instance.__dict__[self.name] = self.func(instance)
                                         ~~~~~~~~~^^^^^^^^^^
  File "C:\Python313\Lib\site-packages\django\urls\resolvers.py", line 708, in urlconf_module
    return import_module(self.urlconf_name)
  File "C:\Python313\Lib\importlib\__init__.py", line 88, in import_module
    return _bootstrap._gcd_import(name[level:], package, level)
           ~~~~~~~~~~~~~~~~~~~~~~^^^^^^^^^^^^^^^^^^^^^^^^^^^^^^
  File "<frozen importlib._bootstrap>", line 1387, in _gcd_import
  File "<frozen importlib._bootstrap>", line 1360, in _find_and_load
  File "<frozen importlib._bootstrap>", line 1331, in _find_and_load_unlocked
  File "<frozen importlib._bootstrap>", line 935, in _load_unlocked
  File "<frozen importlib._bootstrap_external>", line 1022, in exec_module
  File "<frozen importlib._bootstrap>", line 488, in _call_with_frames_removed
  File "C:\inetpub\wwwroot\QueryManager\core\urls.py", line 27, in <module>
    ]+ static(settings.STATIC_URL, document_root=settings.STATIC_ROOT) + \
       ^^^^^^
NameError: name 'static' is not defined
Performing system checks...

[17/Nov/2024 21:51:16] "GET /QueryManager/ HTTP/1.1" 200 13035
[17/Nov/2024 21:51:17] "GET /QueryManager/static/bootstrap.min.css HTTP/1.1" 404 179
[17/Nov/2024 21:51:17] "GET /QueryManager/static/custom.css HTTP/1.1" 404 179
[17/Nov/2024 21:51:17] "GET /QueryManager/static/query_manager.png HTTP/1.1" 404 179
[17/Nov/2024 21:51:17] "GET /QueryManager/static/profile_pics/default2.jpg HTTP/1.1" 404 179
Performing system checks...

System check identified no issues (0 silenced).
November 17, 2024 - 21:51:12
Django version 4.2.16, using settings 'core.settings'
Starting development server at http://127.0.0.1:22915/
Quit the server with CTRL-BREAK.

[17/Nov/2024 21:51:45] "GET /QueryManager/ HTTP/1.1" 200 13035
[17/Nov/2024 21:51:45] "GET /QueryManager/static/profile_pics/default2.jpg HTTP/1.1" 200 10687
[17/Nov/2024 21:51:45] "GET /QueryManager/static/custom.css HTTP/1.1" 200 1925
[17/Nov/2024 21:51:45] "GET /QueryManager/static/query_manager.png HTTP/1.1" 200 64648
[17/Nov/2024 21:51:45] "GET /QueryManager/static/bootstrap.min.css HTTP/1.1" 200 160302
[17/Nov/2024 21:51:53] "GET /QueryManager/ HTTP/1.1" 200 13035
[17/Nov/2024 21:52:02] "GET /QueryManager/admin/ HTTP/1.1" 302 0
[17/Nov/2024 21:52:03] "GET /QueryManager/admin/login/?next=/QueryManager/admin/ HTTP/1.1" 200 4324
[17/Nov/2024 21:52:03] "GET /QueryManager/static/admin/css/login.css HTTP/1.1" 200 951
[17/Nov/2024 21:52:03] "GET /QueryManager/static/admin/css/base.css HTTP/1.1" 200 22092
[17/Nov/2024 21:52:03] "GET /QueryManager/static/admin/css/responsive.css HTTP/1.1" 200 17972
[17/Nov/2024 21:52:03] "GET /QueryManager/static/admin/css/dark_mode.css HTTP/1.1" 200 2804
[17/Nov/2024 21:52:03] "GET /QueryManager/static/admin/css/nav_sidebar.css HTTP/1.1" 200 2810
[17/Nov/2024 21:52:03] "GET /QueryManager/static/admin/js/nav_sidebar.js HTTP/1.1" 200 3063
[17/Nov/2024 21:52:03] "GET /QueryManager/static/admin/js/theme.js HTTP/1.1" 200 1653
[17/Nov/2024 21:52:07] "POST /QueryManager/admin/login/?next=/QueryManager/admin/ HTTP/1.1" 200 4486
[17/Nov/2024 21:52:12] "GET /QueryManager/ HTTP/1.1" 200 13035
[17/Nov/2024 21:52:15] "GET /QueryManager/accounts/login/ HTTP/1.1" 200 4879
[17/Nov/2024 21:52:15] "GET /QueryManager/static/fa4/css/font-awesome.min.css HTTP/1.1" 200 31000
[17/Nov/2024 21:52:15] "GET /QueryManager/static/animate.min.css HTTP/1.1" 200 71750
[17/Nov/2024 21:52:15] "GET /QueryManager/static/jquery-3.5.1.min.js HTTP/1.1" 200 89476
[17/Nov/2024 21:52:15] "GET /QueryManager/static/bootstrap.min.js HTTP/1.1" 200 51039
[17/Nov/2024 21:52:25] "POST /QueryManager/accounts/login/ HTTP/1.1" 200 5287
[17/Nov/2024 21:52:30] "POST /QueryManager/accounts/login/ HTTP/1.1" 200 5287
[17/Nov/2024 21:52:37] "POST /QueryManager/accounts/login/ HTTP/1.1" 200 5287
[17/Nov/2024 21:52:41] "GET /QueryManager/admin/ HTTP/1.1" 302 0
[17/Nov/2024 21:52:42] "GET /QueryManager/admin/login/?next=/QueryManager/admin/ HTTP/1.1" 200 4324
[17/Nov/2024 21:52:50] "POST /QueryManager/admin/login/?next=/QueryManager/admin/ HTTP/1.1" 200 4487
[17/Nov/2024 21:52:57] "POST /QueryManager/admin/login/?next=/QueryManager/admin/ HTTP/1.1" 200 4487
[17/Nov/2024 21:53:57] "POST /QueryManager/admin/login/?next=/QueryManager/admin/ HTTP/1.1" 200 4487
[17/Nov/2024 21:55:44] "POST /QueryManager/admin/login/?next=/QueryManager/admin/ HTTP/1.1" 302 0
[17/Nov/2024 21:55:44] "GET /QueryManager/admin/ HTTP/1.1" 200 8328
[17/Nov/2024 21:55:45] "GET /QueryManager/static/admin/css/dashboard.css HTTP/1.1" 200 441
[17/Nov/2024 21:55:45] "GET /QueryManager/static/admin/img/icon-addlink.svg HTTP/1.1" 200 331
[17/Nov/2024 21:55:45] "GET /QueryManager/static/admin/img/icon-changelink.svg HTTP/1.1" 200 380
[17/Nov/2024 21:55:51] "GET /QueryManager/admin/main/customuser/ HTTP/1.1" 200 12541
[17/Nov/2024 21:55:51] "GET /QueryManager/static/admin/css/changelists.css HTTP/1.1" 200 6878
[17/Nov/2024 21:55:51] "GET /QueryManager/static/admin/js/jquery.init.js HTTP/1.1" 200 347
[17/Nov/2024 21:55:51] "GET /QueryManager/static/admin/js/vendor/jquery/jquery.min.js HTTP/1.1" 200 87533
[17/Nov/2024 21:55:51] "GET /QueryManager/static/admin/js/prepopulate.js HTTP/1.1" 200 1531
[17/Nov/2024 21:55:51] "GET /QueryManager/static/admin/js/core.js HTTP/1.1" 200 6208
[17/Nov/2024 21:55:51] "GET /QueryManager/static/admin/js/actions.js HTTP/1.1" 200 8076
[17/Nov/2024 21:55:51] "GET /QueryManager/static/admin/js/urlify.js HTTP/1.1" 200 7887
[17/Nov/2024 21:55:51] "GET /QueryManager/static/admin/js/admin/RelatedObjectLookups.js HTTP/1.1" 200 9097
[17/Nov/2024 21:55:51] "GET /QueryManager/admin/jsi18n/ HTTP/1.1" 200 3343
[17/Nov/2024 21:55:51] "GET /QueryManager/static/admin/js/vendor/xregexp/xregexp.min.js HTTP/1.1" 200 163184
[17/Nov/2024 21:55:52] "GET /QueryManager/static/admin/js/filters.js HTTP/1.1" 200 978
[17/Nov/2024 21:55:52] "GET /QueryManager/static/admin/img/tooltag-add.svg HTTP/1.1" 200 331
[17/Nov/2024 21:56:02] "GET /QueryManager/admin/main/customuser/11/change/ HTTP/1.1" 200 23832
[17/Nov/2024 21:56:02] "GET /QueryManager/admin/jsi18n/ HTTP/1.1" 200 3343
[17/Nov/2024 21:56:02] "GET /QueryManager/static/admin/css/forms.css HTTP/1.1" 200 8794
[17/Nov/2024 21:56:02] "GET /QueryManager/static/admin/js/admin/DateTimeShortcuts.js HTTP/1.1" 200 19319
[17/Nov/2024 21:56:02] "GET /QueryManager/static/admin/js/calendar.js HTTP/1.1" 200 9141
[17/Nov/2024 21:56:02] "GET /QueryManager/static/admin/js/prepopulate_init.js HTTP/1.1" 200 586
[17/Nov/2024 21:56:02] "GET /QueryManager/static/admin/js/change_form.js HTTP/1.1" 200 606
[17/Nov/2024 21:56:02] "GET /QueryManager/static/admin/css/widgets.css HTTP/1.1" 200 11564
[17/Nov/2024 21:56:03] "GET /QueryManager/static/admin/img/icon-clock.svg HTTP/1.1" 200 677
[17/Nov/2024 21:56:03] "GET /QueryManager/static/admin/img/icon-calendar.svg HTTP/1.1" 200 1086
[17/Nov/2024 21:56:10] "GET /QueryManager/ HTTP/1.1" 200 13759
[17/Nov/2024 21:56:15] "GET /QueryManager/ask-question HTTP/1.1" 200 6732
[17/Nov/2024 21:56:20] "POST /QueryManager/ask-question HTTP/1.1" 302 0
[17/Nov/2024 21:56:21] "GET /QueryManager/ask-question HTTP/1.1" 200 6848
[17/Nov/2024 21:56:27] "GET /QueryManager/ HTTP/1.1" 200 13606
[17/Nov/2024 21:56:30] "GET /QueryManager/detail/13 HTTP/1.1" 301 0
[17/Nov/2024 21:56:30] "GET /QueryManager/detail/13/ HTTP/1.1" 200 10945
[17/Nov/2024 21:56:38] "POST /QueryManager/detail/13/ HTTP/1.1" 200 13095
[17/Nov/2024 21:56:46] "POST /QueryManager/detail/13/ HTTP/1.1" 200 15156
[17/Nov/2024 21:56:51] "GET /QueryManager/ HTTP/1.1" 200 13606
[17/Nov/2024 21:57:01] "GET /QueryManager/accounts/profile/ HTTP/1.1" 200 15114
[17/Nov/2024 21:57:03] "GET /QueryManager/accounts/logout/ HTTP/1.1" 302 0
[17/Nov/2024 21:57:03] "GET /QueryManager/ HTTP/1.1" 200 12882
[17/Nov/2024 21:57:29] "GET /QueryManager/ HTTP/1.1" 200 12882
